import threading
from datetime import timedelta
from unittest import TestCase, skipUnless
from unittest.mock import Mock, patch

import torch
from torch.futures import Future

from torchft.futures import (
    _TIMEOUT_MANAGER,
    context_timeout,
    future_timeout,
    future_wait,
    stream_timeout,
)


class FuturesTest(TestCase):
    def setUp(self) -> None:
        self._original_watchdog_interval = _TIMEOUT_MANAGER._watchdog_interval
        _TIMEOUT_MANAGER._watchdog_interval = timedelta(seconds=1)

    def tearDown(self) -> None:
        _TIMEOUT_MANAGER._watchdog_interval = self._original_watchdog_interval

    def test_future_wait(self) -> None:
        fut = Future()
        with self.assertRaisesRegex(TimeoutError, "future did not complete within"):
            future_wait(fut, timeout=timedelta(seconds=0.01))

        fut = Future()
        fut.set_result(1)
        self.assertEqual(future_wait(fut, timeout=timedelta(seconds=1.0)), 1)

        fut = Future()
        fut.set_exception(RuntimeError("test"))
        with self.assertRaisesRegex(RuntimeError, "test"):
            future_wait(fut, timeout=timedelta(seconds=1.0))

    def test_future_timeout(self) -> None:
        fut = Future()
        timed_fut = future_timeout(fut, timeout=timedelta(seconds=0.01))
        with self.assertRaisesRegex(TimeoutError, "future did not complete within"):
            timed_fut.wait()

    def test_future_timeout_result(self) -> None:
        fut = Future()
        timed_fut = future_timeout(fut, timeout=timedelta(seconds=10))
        fut.set_result(1)
        self.assertEqual(timed_fut.wait(), 1)

    def test_future_timeout_exception(self) -> None:
        fut = Future()
        timed_fut = future_timeout(fut, timeout=timedelta(seconds=10))
        fut.set_exception(RuntimeError("test"))
        with self.assertRaisesRegex(RuntimeError, "test"):
            timed_fut.wait()

    def test_context_timeout(self) -> None:
        barrier: threading.Barrier = threading.Barrier(2)

        def callback() -> None:
            barrier.wait()

        with context_timeout(callback, timedelta(seconds=0.01)):
            # block until timeout fires
            barrier.wait()

        def fail() -> None:
            self.fail("timeout should be cancelled")

        with context_timeout(fail, timedelta(seconds=10)):
            pass

    # pyre-fixme[56]: Pyre was not able to infer the type of decorator
    @skipUnless(torch.cuda.is_available(), "CUDA is required for this test")
    def test_stream_timeout(self) -> None:
        torch.cuda.synchronize()

        def callback() -> None:
            self.fail()

        stream_timeout(callback, timeout=timedelta(seconds=0.01))

        # make sure event completes
        torch.cuda.synchronize()

        # make sure that event is deleted on the deletion queue
        item = _TIMEOUT_MANAGER._del_queue.get(timeout=10.0)
        _TIMEOUT_MANAGER._del_queue.put(item)
        del item

        self.assertEqual(_TIMEOUT_MANAGER._clear_del_queue(), 1)

    # Test that when a timeout handle gets stuck, `sys.exit(1)` is called
    @patch("sys.exit")
    def test_exit_on_stuck_callback(self, mock_exit: Mock) -> None:
        exit_event: threading.Event = threading.Event()

        def custom_exit(_) -> None:
            # 3. When event loop is stuck, exit(1) is called
            nonlocal exit_event
            exit_event.set()

        mock_exit.side_effect = custom_exit

        callback_event: threading.Event = threading.Event()

        def callback() -> None:
            # 2. Make sure callback blocks event loop
            nonlocal callback_event
            callback_event.wait()

        context_event: threading.Event = threading.Event()

        def thread_fn() -> None:
            with context_timeout(callback, timedelta(seconds=0.01)):
                # 1. Make sure context doesn't finish in time
                nonlocal context_event
                context_event.wait()

        thread = threading.Thread(target=thread_fn)
        thread.start()

        # 4. exit event will wake this up
        exit_event.wait()
        mock_exit.assert_called_once_with(1)

        # 5. event loop is still stuck, so let's unblock it
        callback_event.set()

        # 6. unblock the context and make sure it exits
        context_event.set()
        thread.join()
